Workbook

Sheet Hypothèses
A1: ÉVALUATION IMMOBILIÈRE — Rue du Philosophe 23, Genève
A2: Analyse pour Bastien Dumont — Tarmaq / Investissement
A4: PARAMÈTRE | B4: ARCADE (Lot 1) | C4: ATELIER (Lot 2) | D4: COMBINÉ
A5: DONNÉES DU BIEN
A6: Surface (m²) | B6: 33 | C6: 69 | D6: =B6+C6 -> 102
A7: Prix d'achat (CHF) | B7: 375000 | C7: 700000 | D7: =B7+C7 -> 1075000
A8: Prix au m² (CHF/m²) | B8: =B7/B6 -> 11363.636 | C8: =C7/C6 -> 10144.928 | D8: =D7/D6 -> 10539.216
A9: Rénovation (CHF) | B9: 37000 | C9: 0 | D9: =B9+C9 -> 37000
A10: Frais de transaction (3.5%) | B10: =B7*B14 -> 13125 | C10: =C7*C14 -> 24500 | D10: =D7*B14 -> 37625
A11: Investissement total (CHF) | B11: =B7+B9+B10 -> 425125 | C11: =C7+C9+C10 -> 724500 | D11: =D7+D9+D10 -> 1149625
A12: Loyer mensuel cible (CHF) | B12: 1500 | C12: 2500 | D12: =B12+C12 -> 4000
A13: Charges copro mensuelles (CHF) | B13: 100 | C13: 210 | D13: =B13+C13 -> 310
A14: Taux de frais de transaction | B14: 0.035 | C14: 0.035
A15: Taux de vacance | B15: 0.05 | C15: 0.05
A16: Provision entretien (% loyer) | B16: 0.05 | C16: 0.05
A17: Assurance annuelle (CHF) | B17: 300 | C17: 500 | D17: =B17+C17 -> 800
A18: Taux hypothécaire | B18: 0.0175 | C18: 0.0175
A19: LTV (prêt/valeur) | B19: 0.65 | C19: 0.65
A20: Durée amortissement (années) | B20: 15 | C20: 15
A21: Indexation loyer annuelle | B21: 0.01 | C21: 0.01
A22: Croissance charges annuelle | B22: 0.005 | C22: 0.005
A23: Appréciation bien annuelle | B23: 0.015 | C23: 0.015
A25: MÉTRIQUES CLÉS
A26: Loyer annuel brut (CHF) | B26: =B12*12 -> 18000 | C26: =C12*12 -> 30000 | D26: =D12*12 -> 48000
A27: Provision vacance (CHF) | B27: =B26*B15 -> 900 | C27: =C26*C15 -> 1500 | D27: =D26*0.05 -> 2400
A28: Charges copro annuelles (CHF) | B28: =B13*12 -> 1200 | C28: =C13*12 -> 2520 | D28: =D13*12 -> 3720
A29: Provision entretien (CHF) | B29: =B26*B16 -> 900 | C29: =C26*C16 -> 1500 | D29: =D26*0.05 -> 2400
A30: Assurance (CHF) | B30: =B17 -> 300 | C30: =C17 -> 500 | D30: =D17 -> 800
A31: Total charges exploitation (CHF) | B31: =B27+B28+B29+B30 -> 3300 | C31: =C27+C28+C29+C30 -> 6020 | D31: =D27+D28+D29+D30 -> 9320
A32: Revenu net (NOI) (CHF) | B32: =B26-B31 -> 14700 | C32: =C26-C31 -> 23980 | D32: =D26-D31 -> 38680
A34: Rendement brut | B34: =B26/B7 -> 0.048 | C34: =C26/C7 -> 0.042857143 | D34: =D26/D7 -> 0.044651163
A35: Rendement net (sur prix) | B35: =B32/B7 -> 0.0392 | C35: =C32/C7 -> 0.034257143 | D35: =D32/D7 -> 0.035981395
A36: Cap rate (sur investissement total) | B36: =B32/B11 -> 0.034578065 | C36: =C32/C11 -> 0.033098689 | D36: =D32/D11 -> 0.033645754
A38: Montant hypothèque (CHF) | B38: =B7*B19 -> 243750 | C38: =C7*C19 -> 455000 | D38: =D7*0.65 -> 698750
A39: Fonds propres requis (CHF) | B39: =B11-B38 -> 181375 | C39: =C11-C38 -> 269500 | D39: =D11-D38 -> 450875
A40: Intérêts annuels (CHF) | B40: =B38*B18 -> 4265.625 | C40: =C38*C18 -> 7962.5 | D40: =D38*0.0175 -> 12228.125
A41: Amortissement annuel (CHF) | B41: =(B7*0.15)/B20 -> 3750 | C41: =(C7*0.15)/C20 -> 7000 | D41: =(D7*0.15)/15 -> 10750
A42: Service dette annuel (CHF) | B42: =B40+B41 -> 8015.625 | C42: =C40+C41 -> 14962.5 | D42: =D40+D41 -> 22978.125
A43: Cash flow après dette (CHF) | B43: =B32-B42 -> 6684.375 | C43: =C32-C42 -> 9017.5 | D43: =D32-D42 -> 15701.875
A44: Cash-on-cash return | B44: =B43/B39 -> 0.036853894 | C44: =C43/C39 -> 0.033460111 | D44: =D43/D39 -> 0.03482534
...

Sheet ProForma Arcade
A1: PRO FORMA 5 ANS — ARCADE COMMERCIALE (33m²)
B3: Année 0 | C3: Année 1 | D3: Année 2 | E3: Année 3 | F3: Année 4 | G3: Année 5
A4: INVESTISSEMENT
A5: Prix d'achat | B5: -375000
A6: Rénovation | B6: -37000
A7: Frais de transaction | B7: =-Hypothèses!B10 -> -13125
A8: Total investissement | B8: =SUM(B5:B7) -> -425125
A10: REVENUS
A11: Loyer brut annuel | C11: =Hypothèses!B26 -> 18000 | D11: =C11*(1+Hypothèses!B21) -> 18180 | E11: =D11*(1+Hypothèses!B21) -> 18361.8 | F11: =E11*(1+Hypothèses!B21) -> 18545.418 | G11: =F11*(1+Hypothèses!B21) -> 18730.872
A12: Provision vacance (-5%) | C12: =-C11*Hypothèses!B15 -> -900 | D12: =-D11*Hypothèses!B15 -> -909 | E12: =-E11*Hypothèses!B15 -> -918.09 | F12: =-F11*Hypothèses!B15 -> -927.2709 | G12: =-G11*Hypothèses!B15 -> -936.54361
A13: Revenus nets | C13: =C11+C12 -> 17100 | D13: =D11+D12 -> 17271 | E13: =E11+E12 -> 17443.71 | F13: =F11+F12 -> 17618.147 | G13: =G11+G12 -> 17794.329
A15: CHARGES D'EXPLOITATION
A16: Charges copropriété | C16: =Hypothèses!B28 -> 1200 | D16: =C16*(1+Hypothèses!B22) -> 1206 | E16: =D16*(1+Hypothèses!B22) -> 1212.03 | F16: =E16*(1+Hypothèses!B22) -> 1218.0901 | G16: =F16*(1+Hypothèses!B22) -> 1224.1806
A17: Provision entretien | C17: =C11*Hypothèses!B16 -> 900 | D17: =D11*Hypothèses!B16 -> 909 | E17: =E11*Hypothèses!B16 -> 918.09 | F17: =F11*Hypothèses!B16 -> 927.2709 | G17: =G11*Hypothèses!B16 -> 936.54361
A18: Assurance | C18: =Hypothèses!B17 -> 300 | D18: =C18*(1+Hypothèses!B22) -> 301.5 | E18: =D18*(1+Hypothèses!B22) -> 303.0075 | F18: =E18*(1+Hypothèses!B22) -> 304.52254 | G18: =F18*(1+Hypothèses!B22) -> 306.04515
A19: Total charges | C19: =C16+C17+C18 -> 2400 | D19: =D16+D17+D18 -> 2416.5 | E19: =E16+E17+E18 -> 2433.1275 | F19: =F16+F17+F18 -> 2449.8836 | G19: =G16+G17+G18 -> 2466.7694
A21: NOI (Revenu net d'exploitation) | C21: =C13-C19 -> 14700 | D21: =D13-D19 -> 14854.5 | E21: =E13-E19 -> 15010.583 | F21: =F13-F19 -> 15168.264 | G21: =G13-G19 -> 15327.559
A23: SERVICE DE LA DETTE
A24: Intérêts hypothécaires | C24: =Hypothèses!B40 -> 4265.625 | D24: =C24 -> 4265.625 | E24: =D24 -> 4265.625 | F24: =E24 -> 4265.625 | G24: =F24 -> 4265.625
A25: Amortissement | C25: =Hypothèses!B41 -> 3750 | D25: =C25 -> 3750 | E25: =D25 -> 3750 | F25: =E25 -> 3750 | G25: =F25 -> 3750
A26: Total service dette | C26: =C24+C25 -> 8015.625 | D26: =D24+D25 -> 8015.625 | E26: =E24+E25 -> 8015.625 | F26: =F24+F25 -> 8015.625 | G26: =G24+G25 -> 8015.625
A28: CASH FLOW NET | B28: =B8 -> -425125 | C28: =C21-C26 -> 6684.375 | D28: =D21-D26 -> 6838.875 | E28: =E21-E26 -> 6994.9575 | F28: =F21-F26 -> 7152.6385 | G28: =G21-G26 -> 7311.9342
A29: Cash flow cumulé | B29: =B28 -> -425125 | C29: =B29+C28 -> -418440.62 | D29: =C29+D28 -> -411601.75 | E29: =D29+E28 -> -404606.79 | F29: =E29+F28 -> -397454.15 | G29: =F29+G28 -> -390142.22
A31: VALEUR DU BIEN
A32: Valeur estimée | B32: =Hypothèses!B7 -> 375000 | C32: =B32*(1+Hypothèses!B23) -> 380625 | D32: =C32*(1+Hypothèses!B23) -> 386334.38 | E32: =D32*(1+Hypothèses!B23) -> 392129.39 | F32: =E32*(1+Hypothèses!B23) -> 398011.33 | G32: =F32*(1+Hypothèses!B23) -> 403981.5
A33: Plus-value latente | C33: =C32-B32 -> 5625 | D33: =D32-B32 -> 11334.375 | E33: =E32-B32 -> 17129.391 | F33: =F32-B32 -> 23011.331 | G33: =G32-B32 -> 28981.501
A34: Rendement total (cash + PV) | C34: =C28+C33 -> 12309.375 | D34: =D28+D33 -> 18173.25 | E34: =E28+E33 -> 24124.348 | F34: =F28+F33 -> 30163.97 | G34: =G28+G33 -> 36293.436

Sheet ProForma Atelier
A1: PRO FORMA 5 ANS — ATELIER (69m²)
B3: Année 0 | C3: Année 1 | D3: Année 2 | E3: Année 3 | F3: Année 4 | G3: Année 5
A4: INVESTISSEMENT
A5: Prix d'achat | B5: -700000
A6: Rénovation | B6: 0
A7: Frais de transaction | B7: =-Hypothèses!C10 -> -24500
A8: Total investissement | B8: =SUM(B5:B7) -> -724500
A10: REVENUS
A11: Loyer brut annuel | C11: =Hypothèses!C26 -> 30000 | D11: =C11*(1+Hypothèses!C21) -> 30300 | E11: =D11*(1+Hypothèses!C21) -> 30603 | F11: =E11*(1+Hypothèses!C21) -> 30909.03 | G11: =F11*(1+Hypothèses!C21) -> 31218.12
A12: Provision vacance (-5%) | C12: =-C11*Hypothèses!C15 -> -1500 | D12: =-D11*Hypothèses!C15 -> -1515 | E12: =-E11*Hypothèses!C15 -> -1530.15 | F12: =-F11*Hypothèses!C15 -> -1545.4515 | G12: =-G11*Hypothèses!C15 -> -1560.906
A13: Revenus nets | C13: =C11+C12 -> 28500 | D13: =D11+D12 -> 28785 | E13: =E11+E12 -> 29072.85 | F13: =F11+F12 -> 29363.578 | G13: =G11+G12 -> 29657.214
A15: CHARGES D'EXPLOITATION
A16: Charges copropriété | C16: =Hypothèses!C28 -> 2520 | D16: =C16*(1+Hypothèses!C22) -> 2532.6 | E16: =D16*(1+Hypothèses!C22) -> 2545.263 | F16: =E16*(1+Hypothèses!C22) -> 2557.9893 | G16: =F16*(1+Hypothèses!C22) -> 2570.7793
A17: Provision entretien | C17: =C11*Hypothèses!C16 -> 1500 | D17: =D11*Hypothèses!C16 -> 1515 | E17: =E11*Hypothèses!C16 -> 1530.15 | F17: =F11*Hypothèses!C16 -> 1545.4515 | G17: =G11*Hypothèses!C16 -> 1560.906
A18: Assurance | C18: =Hypothèses!C17 -> 500 | D18: =C18*(1+Hypothèses!C22) -> 502.5 | E18: =D18*(1+Hypothèses!C22) -> 505.0125 | F18: =E18*(1+Hypothèses!C22) -> 507.53756 | G18: =F18*(1+Hypothèses!C22) -> 510.07525
A19: Total charges | C19: =C16+C17+C18 -> 4520 | D19: =D16+D17+D18 -> 4550.1 | E19: =E16+E17+E18 -> 4580.4255 | F19: =F16+F17+F18 -> 4610.9784 | G19: =G16+G17+G18 -> 4641.7605
A21: NOI (Revenu net d'exploitation) | C21: =C13-C19 -> 23980 | D21: =D13-D19 -> 24234.9 | E21: =E13-E19 -> 24492.425 | F21: =F13-F19 -> 24752.6 | G21: =G13-G19 -> 25015.454
A23: SERVICE DE LA DETTE
A24: Intérêts hypothécaires | C24: =Hypothèses!C40 -> 7962.5 | D24: =C24 -> 7962.5 | E24: =D24 -> 7962.5 | F24: =E24 -> 7962.5 | G24: =F24 -> 7962.5
A25: Amortissement | C25: =Hypothèses!C41 -> 7000 | D25: =C25 -> 7000 | E25: =D25 -> 7000 | F25: =E25 -> 7000 | G25: =F25 -> 7000
A26: Total service dette | C26: =C24+C25 -> 14962.5 | D26: =D24+D25 -> 14962.5 | E26: =E24+E25 -> 14962.5 | F26: =F24+F25 -> 14962.5 | G26: =G24+G25 -> 14962.5
A28: CASH FLOW NET | B28: =B8 -> -724500 | C28: =C21-C26 -> 9017.5 | D28: =D21-D26 -> 9272.4 | E28: =E21-E26 -> 9529.9245 | F28: =F21-F26 -> 9790.1001 | G28: =G21-G26 -> 10052.954
A29: Cash flow cumulé | B29: =B28 -> -724500 | C29: =B29+C28 -> -715482.5 | D29: =C29+D28 -> -706210.1 | E29: =D29+E28 -> -696680.18 | F29: =E29+F28 -> -686890.08 | G29: =F29+G28 -> -676837.12
A31: VALEUR DU BIEN
A32: Valeur estimée | B32: =Hypothèses!C7 -> 700000 | C32: =B32*(1+Hypothèses!C23) -> 710500 | D32: =C32*(1+Hypothèses!C23) -> 721157.5 | E32: =D32*(1+Hypothèses!C23) -> 731974.86 | F32: =E32*(1+Hypothèses!C23) -> 742954.49 | G32: =F32*(1+Hypothèses!C23) -> 754098.8
A33: Plus-value latente | C33: =C32-B32 -> 10500 | D33: =D32-B32 -> 21157.5 | E33: =E32-B32 -> 31974.862 | F33: =F32-B32 -> 42954.485 | G33: =G32-B32 -> 54098.803
A34: Rendement total (cash + PV) | C34: =C28+C33 -> 19517.5 | D34: =D28+D33 -> 30429.9 | E34: =E28+E33 -> 41504.787 | F34: =F28+F33 -> 52744.586 | G34: =G28+G33 -> 64151.756

Sheet Comparaison
A1: MATRICE DE DÉCISION — COMPARAISON DES SCÉNARIOS
B3: Arcade seule | C3: Atelier seul | D3: Les 2 lots | E3: Location seule
A4: Investissement total (CHF) | B4: =Hypothèses!B11 -> 425125 | C4: =Hypothèses!C11 -> 724500 | D4: =Hypothèses!D11 -> 1149625 | E4: 0
A5: Fonds propres requis (CHF) | B5: =Hypothèses!B39 -> 181375 | C5: =Hypothèses!C39 -> 269500 | D5: =Hypothèses!D39 -> 450875 | E5: 0
A6: Loyer annuel brut (CHF) | B6: =Hypothèses!B26 -> 18000 | C6: =Hypothèses!C26 -> 30000 | D6: =Hypothèses!D26 -> 48000 | E6: =-Hypothèses!D26 -> -48000
A7: NOI annuel (CHF) | B7: =Hypothèses!B32 -> 14700 | C7: =Hypothèses!C32 -> 23980 | D7: =Hypothèses!D32 -> 38680 | E7: 0
A8: Cash flow après dette (CHF) | B8: =Hypothèses!B43 -> 6684.375 | C8: =Hypothèses!C43 -> 9017.5 | D8: =Hypothèses!D43 -> 15701.875 | E8: =-Hypothèses!D26 -> -48000
A9: Rendement brut | B9: =Hypothèses!B34 -> 0.048 | C9: =Hypothèses!C34 -> 0.042857143 | D9: =Hypothèses!D34 -> 0.044651163
A10: Rendement net | B10: =Hypothèses!B35 -> 0.0392 | C10: =Hypothèses!C35 -> 0.034257143 | D10: =Hypothèses!D35 -> 0.035981395
A11: Cap rate | B11: =Hypothèses!B36 -> 0.034578065 | C11: =Hypothèses!C36 -> 0.033098689 | D11: =Hypothèses!D36 -> 0.033645754
A12: Cash-on-cash return | B12: =Hypothèses!B44 -> 0.036853894 | C12: =Hypothèses!C44 -> 0.033460111 | D12: =Hypothèses!D44 -> 0.03482534
A13: Seuil rentabilité occupancy | B13: =Hypothèses!B45 -> 0.18333333 | C13: =Hypothèses!C45 -> 0.20066667 | D13: =Hypothèses!D45 -> 0.19416667
A15: ANALYSE DES RISQUES
A17: Risque | B17: Impact | C17: Probabilité | D17: Mitigation
A18: Vacance prolongée (>3 mois) | B18: Élevé | C18: Moyen | D18: Bail commercial longue durée, emplacement central
A19: Travaux copro imprévus | B19: Moyen | C19: Élevé | D19: Bâtiment pré-1919, vérifier fonds de rénovation
A20: Hausse taux hypothécaires | B20: Moyen | C20: Moyen | D20: Taux fixe 5-10 ans au closing
A21: Baisse marché immobilier | B21: Élevé | C21: Faible | D21: Genève = marché résilient, horizon long terme
A22: Réglementation locative | B22: Faible | C22: Moyen | D22: Bail commercial moins régulé que résidentiel
